2020-06-17 21:53:24,651 py30 INFO test_login.py-29 line：***********  开始执行测试用例 **************
2020-06-17 21:53:24,651 py30 INFO test_login.py-30 line：测试数据为：{'user': 'python27', 'passwd': 'lemonban66666', 'check': '{"code": 0, "msg": "登录成功"}'}
2020-06-17 21:53:24,651 py30 INFO test_login.py-33 line：实际运行结果为：{'code': 1, 'msg': '账号或密码不正确'}
2020-06-17 21:53:24,652 py30 ERROR test_login.py-38 line：断言失败，用例不通过！
Traceback (most recent call last):
  File "C:\Program Files\JetBrains\PyCharm Community Edition 2020.1\plugins\python-ce\helpers\pycharm\teamcity\diff_tools.py", line 32, in _patched_equals
    old(self, first, second, msg)
  File "D:\python37\lib\unittest\case.py", line 839, in assertEqual
    assertion_func(first, second, msg=msg)
  File "D:\python37\lib\unittest\case.py", line 1138, in assertDictEqual
    self.fail(self._formatMessage(msg, standardMsg))
  File "D:\python37\lib\unittest\case.py", line 680, in fail
    raise self.failureException(msg)
AssertionError: {'code': 1, 'msg': '账号或密码不正确'} != {'code': 0, 'msg': '登录成功'}
- {'code': 1, 'msg': '账号或密码不正确'}
?          ^          ^^^^^^^^

+ {'code': 0, 'msg': '登录成功'}
?          ^          ^^^^


During handling of the above exception, another exception occurred:

Traceback (most recent call last):
  File "D:\Pychram-Workspace\py30\class_excel_logger\test_login.py", line 36, in test_login
    self.assertEqual(res,eval(case["check"]))
  File "C:\Program Files\JetBrains\PyCharm Community Edition 2020.1\plugins\python-ce\helpers\pycharm\teamcity\diff_tools.py", line 38, in _patched_equals
    raise error
teamcity.diff_tools.EqualsAssertionError:  :: {'code': 1, 'msg': '账号或密码不正确'} != {'code': 0, 'msg': '登录成功'}
2020-06-17 21:53:24,657 py30 INFO test_login.py-41 line：***********  测试用例执行结束 **************
2020-06-17 21:53:24,658 py30 INFO test_login.py-29 line：***********  开始执行测试用例 **************
2020-06-17 21:53:24,659 py30 INFO test_login.py-30 line：测试数据为：{'user': 'python27', 'passwd': 'lemonban11', 'check': '{"code": 1, "msg": "账号或密码不正确"}'}
2020-06-17 21:53:24,659 py30 INFO test_login.py-33 line：实际运行结果为：{'code': 1, 'msg': '账号或密码不正确'}
2020-06-17 21:53:24,659 py30 INFO test_login.py-40 line：断言成功，用例通过！
2020-06-17 21:53:24,659 py30 INFO test_login.py-41 line：***********  测试用例执行结束 **************
2020-06-17 21:53:24,660 py30 INFO test_login.py-29 line：***********  开始执行测试用例 **************
2020-06-17 21:53:24,660 py30 INFO test_login.py-30 line：测试数据为：{'user': 'python25', 'passwd': 'lemonban', 'check': '{"code": 1, "msg": "账号或密码不正确"}'}
2020-06-17 21:53:24,660 py30 INFO test_login.py-33 line：实际运行结果为：{'code': 1, 'msg': '账号或密码不正确'}
2020-06-17 21:53:24,660 py30 INFO test_login.py-40 line：断言成功，用例通过！
2020-06-17 21:53:24,660 py30 INFO test_login.py-41 line：***********  测试用例执行结束 **************
2020-06-17 21:56:39,367 py30 INFO test_login.py-29 line：***********  开始执行测试用例 **************
2020-06-17 21:56:39,368 py30 INFO test_login.py-30 line：测试数据为：{'user': 'python27', 'passwd': 'lemonban66666', 'check': '{"code": 0, "msg": "登录成功"}'}
2020-06-17 21:56:39,369 py30 INFO test_login.py-33 line：实际运行结果为：{'code': 1, 'msg': '账号或密码不正确'}
2020-06-17 21:56:39,371 py30 ERROR test_login.py-38 line：断言失败，用例不通过！
Traceback (most recent call last):
  File "C:\Program Files\JetBrains\PyCharm Community Edition 2020.1\plugins\python-ce\helpers\pycharm\teamcity\diff_tools.py", line 32, in _patched_equals
    old(self, first, second, msg)
  File "D:\python37\lib\unittest\case.py", line 839, in assertEqual
    assertion_func(first, second, msg=msg)
  File "D:\python37\lib\unittest\case.py", line 1138, in assertDictEqual
    self.fail(self._formatMessage(msg, standardMsg))
  File "D:\python37\lib\unittest\case.py", line 680, in fail
    raise self.failureException(msg)
AssertionError: {'code': 1, 'msg': '账号或密码不正确'} != {'code': 0, 'msg': '登录成功'}
- {'code': 1, 'msg': '账号或密码不正确'}
?          ^          ^^^^^^^^

+ {'code': 0, 'msg': '登录成功'}
?          ^          ^^^^


During handling of the above exception, another exception occurred:

Traceback (most recent call last):
  File "D:\Pychram-Workspace\py30\class_excel_logger\test_login.py", line 36, in test_login
    self.assertEqual(res,eval(case["check"]))
  File "C:\Program Files\JetBrains\PyCharm Community Edition 2020.1\plugins\python-ce\helpers\pycharm\teamcity\diff_tools.py", line 38, in _patched_equals
    raise error
teamcity.diff_tools.EqualsAssertionError:  :: {'code': 1, 'msg': '账号或密码不正确'} != {'code': 0, 'msg': '登录成功'}
2020-06-17 21:56:39,379 py30 INFO test_login.py-29 line：***********  开始执行测试用例 **************
2020-06-17 21:56:39,380 py30 INFO test_login.py-30 line：测试数据为：{'user': 'python27', 'passwd': 'lemonban11', 'check': '{"code": 1, "msg": "账号或密码不正确"}'}
2020-06-17 21:56:39,380 py30 INFO test_login.py-33 line：实际运行结果为：{'code': 1, 'msg': '账号或密码不正确'}
2020-06-17 21:56:39,380 py30 INFO test_login.py-41 line：断言成功，用例通过！
2020-06-17 21:56:39,380 py30 INFO test_login.py-42 line：***********  测试用例执行结束 **************
2020-06-17 21:56:39,380 py30 INFO test_login.py-29 line：***********  开始执行测试用例 **************
2020-06-17 21:56:39,380 py30 INFO test_login.py-30 line：测试数据为：{'user': 'python25', 'passwd': 'lemonban', 'check': '{"code": 1, "msg": "账号或密码不正确"}'}
2020-06-17 21:56:39,380 py30 INFO test_login.py-33 line：实际运行结果为：{'code': 1, 'msg': '账号或密码不正确'}
2020-06-17 21:56:39,380 py30 INFO test_login.py-41 line：断言成功，用例通过！
2020-06-17 21:56:39,381 py30 INFO test_login.py-42 line：***********  测试用例执行结束 **************
2020-06-17 21:57:17,552 py30 INFO test_login.py-29 line：***********  开始执行测试用例 **************
2020-06-17 21:57:17,552 py30 INFO test_login.py-30 line：测试数据为：{'user': 'python27', 'passwd': 'lemonban66666', 'check': '{"code": 0, "msg": "登录成功"}'}
2020-06-17 21:57:17,552 py30 INFO test_login.py-33 line：实际运行结果为：{'code': 1, 'msg': '账号或密码不正确'}
2020-06-17 21:57:17,553 py30 ERROR test_login.py-38 line：断言失败，用例不通过！
Traceback (most recent call last):
  File "D:\Pychram-Workspace\py30\class_excel_logger\test_login.py", line 36, in test_login
    self.assertEqual(res,eval(case["check"]))
  File "D:\python37\lib\unittest\case.py", line 839, in assertEqual
    assertion_func(first, second, msg=msg)
  File "D:\python37\lib\unittest\case.py", line 1138, in assertDictEqual
    self.fail(self._formatMessage(msg, standardMsg))
  File "D:\python37\lib\unittest\case.py", line 680, in fail
    raise self.failureException(msg)
AssertionError: {'code': 1, 'msg': '账号或密码不正确'} != {'code': 0, 'msg': '登录成功'}
- {'code': 1, 'msg': '账号或密码不正确'}
?          ^          ^^^^^^^^

+ {'code': 0, 'msg': '登录成功'}
?          ^          ^^^^

2020-06-17 21:57:17,561 py30 INFO test_login.py-29 line：***********  开始执行测试用例 **************
2020-06-17 21:57:17,561 py30 INFO test_login.py-30 line：测试数据为：{'user': 'python27', 'passwd': 'lemonban11', 'check': '{"code": 1, "msg": "账号或密码不正确"}'}
2020-06-17 21:57:17,561 py30 INFO test_login.py-33 line：实际运行结果为：{'code': 1, 'msg': '账号或密码不正确'}
2020-06-17 21:57:17,561 py30 INFO test_login.py-41 line：断言成功，用例通过！
2020-06-17 21:57:17,561 py30 INFO test_login.py-42 line：***********  测试用例执行结束 **************
2020-06-17 21:57:17,561 py30 INFO test_login.py-29 line：***********  开始执行测试用例 **************
2020-06-17 21:57:17,561 py30 INFO test_login.py-30 line：测试数据为：{'user': 'python25', 'passwd': 'lemonban', 'check': '{"code": 1, "msg": "账号或密码不正确"}'}
2020-06-17 21:57:17,562 py30 INFO test_login.py-33 line：实际运行结果为：{'code': 1, 'msg': '账号或密码不正确'}
2020-06-17 21:57:17,562 py30 INFO test_login.py-41 line：断言成功，用例通过！
2020-06-17 21:57:17,562 py30 INFO test_login.py-42 line：***********  测试用例执行结束 **************
